Workbook

Sheet LBO
B2: Atalanta B.C.: the 2022 Pagliuca deal as a holding-company LBO
B3: EUR millions unless stated. Illustrative model built on public figures; not a valuation of the club.
B4: Legend: | D4: Input | E4: Calculation | F4: Same-tab link | G4: Cross-tab link | H4: Key output
B6: 1. TRANSACTION ASSUMPTIONS | K6: Source / note
B7: Entry date (closing, bond issue) | C7: date | D7: 44652 | K7: Spring 2022. BeBeez (2022)
B8: Club equity value at entry (100%) | C8: €m | D8: 450 | K8: Mid-point of press range EUR 400-500m. Il Foglio (2022)
B9: Look-through stake in the club at entry | C9: % | D9: 0.47 | K9: 55% of La Dea H = about 47% of the club
B10: Stake in La Dea H at entry | C10: % | D10: 0.55 | K10: Calcio e Finanza (2022)
B11: Stake in La Dea H after follow-on | C11: % | D11: 0.62 | K11: After the EUR 72m capital increase. Calcio e Finanza (2025)
B12: Look-through stake after follow-on | C12: % | D12: =D9*D11/D10 -> 0.52981818 | K12: Holding's stake in the club unchanged
B13: PIK toggle bond (Athena S.p.A.) | C13: €m | D13: 152.5 | K13: 8% cash / 8.75% PIK, due Apr 2027. InvestireOggi; BeBeez
B14: PIK rate | C14: % | D14: 0.0875 | K14: Assumption: interest always paid in kind (no dividends up from the club)
B15: Vendor loan (Percassi family) | C15: €m | D15: 23 | K15: Calcio e Finanza (2023)
B16: Vendor loan interest (accrued) | C16: % | D16: 0 | K16: Assumption: terms not public; bullet repaid at face
B17: Follow-on date | C17: date | D17: 45672 | K17: Capital increase at La Dea H, January 2025
B18: Follow-on equity (US share) | C18: €m | D18: 67 | K18: EUR 67m of EUR 72m. Calcio e Finanza (2025)
B19: Exit date | C19: date | D19: 46507 | K19: Base case: bond maturity
B20: Exit multiple (EV / LTM revenue) | C20: x | D20: 2 | K20: 2022 entry was about 1.85x 2021 revenue
B21: Revenue growth after 2024/25 (p.a.) | C21: % | D21: 0 | K21: Assumption: flat. H1 2025/26 revenue was 15% lower than H1 2024/25
B23: 2. SOURCES & USES AT ENTRY
B24: Uses | D24: €m | E24: % total | F24: x Rev 2021
B25: Purchase of look-through stake | D25: =$D$8*$D$9 -> 211.5 | E25: =D25/D$26 -> 1 | F25: =$D$8/$D$40 -> 1.8549052
B26: Total uses | D26: =SUM(D25:D25) -> 211.5 | E26: =D26/D$26 -> 1 | F26: =$D$8/$D$40 -> 1.8549052
B28: Sources
B29: PIK toggle bond | D29: =$D$13 -> 152.5 | E29: =D29/D$32 -> 0.72104019
B30: Vendor loan | D30: =$D$15 -> 23 | E30: =D30/D$32 -> 0.10874704
B31: Sponsor equity (plug, incl. Arctos) | D31: =D26-D29-D30 -> 36 | E31: =D31/D$32 -> 0.17021277
B32: Total sources | D32: =SUM(D29:D31) -> 211.5 | E32: =D32/D$32 -> 1
B34: Entry LTV (holding debt / price) | D34: =(D29+D30)/D26 -> 0.82978723
B35: Implied entry multiple (EV / 2021 revenue) | D35: =$D$8/D40 -> 1.8549052
B36: Check: sources - uses (should be zero) | D36: =D32-D26 -> 0
B38: 3. OPERATING MODEL: ATALANTA B.C. (CLUB LEVEL)
B39: Financial year | D39: 2021A | E39: 2022/23A | F39: 2023/24A | G39: 2024/25A | H39: 2025/26E | I39: 2026/27E | K39: FY2021 = calendar year; from 2022/23 July-June (Jan-Jun 2022 six-month period omitted)
B40: Total revenue | D40: 242.6 | E40: 193.7 | F40: 243.7 | G40: 320.8 | H40: =G40*(1+$D$21) -> 320.8 | I40: =H40*(1+$D$21) -> 320.8 | K40: Accounts via Calcio e Finanza; 2022/23 and 2023/24 as restated
B41: Growth | E41: =E40/D40-1 -> -0.20156636 | F41: =F40/E40-1 -> 0.25813113 | G41: =G40/F40-1 -> 0.31637259 | H41: =H40/G40-1 -> 0 | I41: =I40/H40-1 -> 0
B42: of which gains on player disposals | D42: 53.6 | E42: 63.2 | F42: 71 | G42: 100.9 | K42: Calcio e Finanza; QuiFinanza
B43: Gains as % of revenue | D43: =D42/D40 -> 0.22093982 | E43: =E42/E40 -> 0.32627775 | F43: =F42/F40 -> 0.29134181 | G43: =G42/G40 -> 0.31452618
B44: Structural revenue (ex player trading) | D44: =D40-D42 -> 189 | E44: =E40-E42 -> 130.5 | F44: =F40-F42 -> 172.7 | G44: =G40-G42 -> 219.9
B45: Net profit | D45: 35.1 | E45: 5.6 | F45: 11.8 | G45: 37.8
B46: Net margin | D46: =D45/D40 -> 0.14468261 | E46: =E45/E40 -> 0.028910687 | F46: =F45/F40 -> 0.048420189 | G46: =G45/G40 -> 0.11783042
...

Sheet Sens Calc
B2: Helper: dated sponsor cash flows behind each IRR sensitivity cell (LBO tab, section 6)
B3: Each block: three flows (entry equity, follow-on, exit proceeds) and their dates; XIRR in the last row.
B5: Block for irr_v0
B6: Row 1: entry equity | C6: =LBO!$D$7 -> 44652 | D6: =-(LBO!$D$103*LBO!$D$9-LBO!$D$13-LBO!$D$15) -> -12.5 | E6: =-(LBO!$D$103*LBO!$D$9-LBO!$D$13-LBO!$D$15) -> -12.5 | F6: =-(LBO!$D$103*LBO!$D$9-LBO!$D$13-LBO!$D$15) -> -12.5 | G6: =-(LBO!$D$103*LBO!$D$9-LBO!$D$13-LBO!$D$15) -> -12.5 | H6: =-(LBO!$D$103*LBO!$D$9-LBO!$D$13-LBO!$D$15) -> -12.5
B7: Follow-on equity | C7: =LBO!$D$17 -> 45672 | D7: =-LBO!$D$18 -> -67 | E7: =-LBO!$D$18 -> -67 | F7: =-LBO!$D$18 -> -67 | G7: =-LBO!$D$18 -> -67 | H7: =-LBO!$D$18 -> -67
B8: Exit proceeds | C8: =LBO!$D$19 -> 46507 | D8: =LBO!E95*-(D6+D7) -> 0 | E8: =LBO!F95*-(E6+E7) -> 40.941674 | F8: =LBO!G95*-(F6+F7) -> 83.433092 | G8: =LBO!H95*-(G6+G7) -> 125.92451 | H8: =LBO!I95*-(H6+H7) -> 168.41593
B9: IRR (XIRR) | D9: =IF(D8>0,XIRR(D6:D8,$C6:$C8),-1) -> -1 | E9: =IF(E8>0,XIRR(E6:E8,$C6:$C8),-1) -> -0.22407769 | F9: =IF(F8>0,XIRR(F6:F8,$C6:$C8),-1) -> 0.017803849 | G9: =IF(G8>0,XIRR(G6:G8,$C6:$C8),-1) -> 0.17711647 | H9: =IF(H8>0,XIRR(H6:H8,$C6:$C8),-1) -> 0.29720877
B11: Row 2: entry equity | C11: =LBO!$D$7 -> 44652 | D11: =-(LBO!$D$104*LBO!$D$9-LBO!$D$13-LBO!$D$15) -> -24.25 | E11: =-(LBO!$D$104*LBO!$D$9-LBO!$D$13-LBO!$D$15) -> -24.25 | F11: =-(LBO!$D$104*LBO!$D$9-LBO!$D$13-LBO!$D$15) -> -24.25 | G11: =-(LBO!$D$104*LBO!$D$9-LBO!$D$13-LBO!$D$15) -> -24.25 | H11: =-(LBO!$D$104*LBO!$D$9-LBO!$D$13-LBO!$D$15) -> -24.25
B12: Follow-on equity | C12: =LBO!$D$17 -> 45672 | D12: =-LBO!$D$18 -> -67 | E12: =-LBO!$D$18 -> -67 | F12: =-LBO!$D$18 -> -67 | G12: =-LBO!$D$18 -> -67 | H12: =-LBO!$D$18 -> -67
B13: Exit proceeds | C13: =LBO!$D$19 -> 46507 | D13: =LBO!E96*-(D11+D12) -> 0 | E13: =LBO!F96*-(E11+E12) -> 40.941674 | F13: =LBO!G96*-(F11+F12) -> 83.433092 | G13: =LBO!H96*-(G11+G12) -> 125.92451 | H13: =LBO!I96*-(H11+H12) -> 168.41593
B14: IRR (XIRR) | D14: =IF(D13>0,XIRR(D11:D13,$C11:$C13),-1) -> -1 | E14: =IF(E13>0,XIRR(E11:E13,$C11:$C13),-1) -> -0.24566594 | F14: =IF(F13>0,XIRR(F11:F13,$C11:$C13),-1) -> -0.029335017 | G14: =IF(G13>0,XIRR(G11:G13,$C11:$C13),-1) -> 0.10901888 | H14: =IF(H13>0,XIRR(H11:H13,$C11:$C13),-1) -> 0.21193494
B16: Row 3: entry equity | C16: =LBO!$D$7 -> 44652 | D16: =-(LBO!$D$105*LBO!$D$9-LBO!$D$13-LBO!$D$15) -> -36 | E16: =-(LBO!$D$105*LBO!$D$9-LBO!$D$13-LBO!$D$15) -> -36 | F16: =-(LBO!$D$105*LBO!$D$9-LBO!$D$13-LBO!$D$15) -> -36 | G16: =-(LBO!$D$105*LBO!$D$9-LBO!$D$13-LBO!$D$15) -> -36 | H16: =-(LBO!$D$105*LBO!$D$9-LBO!$D$13-LBO!$D$15) -> -36
B17: Follow-on equity | C17: =LBO!$D$17 -> 45672 | D17: =-LBO!$D$18 -> -67 | E17: =-LBO!$D$18 -> -67 | F17: =-LBO!$D$18 -> -67 | G17: =-LBO!$D$18 -> -67 | H17: =-LBO!$D$18 -> -67
B18: Exit proceeds | C18: =LBO!$D$19 -> 46507 | D18: =LBO!E97*-(D16+D17) -> 0 | E18: =LBO!F97*-(E16+E17) -> 40.941674 | F18: =LBO!G97*-(F16+F17) -> 83.433092 | G18: =LBO!H97*-(G16+G17) -> 125.92451 | H18: =LBO!I97*-(H16+H17) -> 168.41593
B19: IRR (XIRR) | D19: =IF(D18>0,XIRR(D16:D18,$C16:$C18),-1) -> -1 | E19: =IF(E18>0,XIRR(E16:E18,$C16:$C18),-1) -> -0.26316639 | F19: =IF(F18>0,XIRR(F16:F18,$C16:$C18),-1) -> -0.063579559 | G19: =IF(G18>0,XIRR(G16:G18,$C16:$C18),-1) -> 0.062416737 | H19: =IF(H18>0,XIRR(H16:H18,$C16:$C18),-1) -> 0.15572877
B21: Row 4: entry equity | C21: =LBO!$D$7 -> 44652 | D21: =-(LBO!$D$106*LBO!$D$9-LBO!$D$13-LBO!$D$15) -> -47.75 | E21: =-(LBO!$D$106*LBO!$D$9-LBO!$D$13-LBO!$D$15) -> -47.75 | F21: =-(LBO!$D$106*LBO!$D$9-LBO!$D$13-LBO!$D$15) -> -47.75 | G21: =-(LBO!$D$106*LBO!$D$9-LBO!$D$13-LBO!$D$15) -> -47.75 | H21: =-(LBO!$D$106*LBO!$D$9-LBO!$D$13-LBO!$D$15) -> -47.75
B22: Follow-on equity | C22: =LBO!$D$17 -> 45672 | D22: =-LBO!$D$18 -> -67 | E22: =-LBO!$D$18 -> -67 | F22: =-LBO!$D$18 -> -67 | G22: =-LBO!$D$18 -> -67 | H22: =-LBO!$D$18 -> -67
B23: Exit proceeds | C23: =LBO!$D$19 -> 46507 | D23: =LBO!E98*-(D21+D22) -> 0 | E23: =LBO!F98*-(E21+E22) -> 40.941674 | F23: =LBO!G98*-(F21+F22) -> 83.433092 | G23: =LBO!H98*-(G21+G22) -> 125.92451 | H23: =LBO!I98*-(H21+H22) -> 168.41593
B24: IRR (XIRR) | D24: =IF(D23>0,XIRR(D21:D23,$C21:$C23),-1) -> -1 | E24: =IF(E23>0,XIRR(E21:E23,$C21:$C23),-1) -> -0.27788552 | F24: =IF(F23>0,XIRR(F21:F23,$C21:$C23),-1) -> -0.090439094 | G24: =IF(G23>0,XIRR(G21:G23,$C21:$C23),-1) -> 0.027094408 | H24: =IF(H23>0,XIRR(H21:H23,$C21:$C23),-1) -> 0.11399015
B26: Row 5: entry equity | C26: =LBO!$D$7 -> 44652 | D26: =-(LBO!$D$107*LBO!$D$9-LBO!$D$13-LBO!$D$15) -> -59.5 | E26: =-(LBO!$D$107*LBO!$D$9-LBO!$D$13-LBO!$D$15) -> -59.5 | F26: =-(LBO!$D$107*LBO!$D$9-LBO!$D$13-LBO!$D$15) -> -59.5 | G26: =-(LBO!$D$107*LBO!$D$9-LBO!$D$13-LBO!$D$15) -> -59.5 | H26: =-(LBO!$D$107*LBO!$D$9-LBO!$D$13-LBO!$D$15) -> -59.5
B27: Follow-on equity | C27: =LBO!$D$17 -> 45672 | D27: =-LBO!$D$18 -> -67 | E27: =-LBO!$D$18 -> -67 | F27: =-LBO!$D$18 -> -67 | G27: =-LBO!$D$18 -> -67 | H27: =-LBO!$D$18 -> -67
B28: Exit proceeds | C28: =LBO!$D$19 -> 46507 | D28: =LBO!E99*-(D26+D27) -> 0 | E28: =LBO!F99*-(E26+E27) -> 40.941674 | F28: =LBO!G99*-(F26+F27) -> 83.433092 | G28: =LBO!H99*-(G26+G27) -> 125.92451 | H28: =LBO!I99*-(H26+H27) -> 168.41593
B29: IRR (XIRR) | D29: =IF(D28>0,XIRR(D26:D28,$C26:$C28),-1) -> -1 | E29: =IF(E28>0,XIRR(E26:E28,$C26:$C28),-1) -> -0.29058474 | F29: =IF(F28>0,XIRR(F26:F28,$C26:$C28),-1) -> -0.11250038 | G29: =IF(G28>0,XIRR(G26:G28,$C26:$C28),-1) -> -0.0012654816 | H29: =IF(H28>0,XIRR(H26:H28,$C26:$C28),-1) -> 0.080920915
B32: Block for irr_dt
B33: Row 1: entry equity | C33: =LBO!$D$7 -> 44652 | D33: =-(LBO!$D$8*LBO!$D$9-LBO!$D$13-LBO!$D$15) -> -36 | E33: =-(LBO!$D$8*LBO!$D$9-LBO!$D$13-LBO!$D$15) -> -36 | F33: =-(LBO!$D$8*LBO!$D$9-LBO!$D$13-LBO!$D$15) -> -36 | G33: =-(LBO!$D$8*LBO!$D$9-LBO!$D$13-LBO!$D$15) -> -36 | H33: =-(LBO!$D$8*LBO!$D$9-LBO!$D$13-LBO!$D$15) -> -36
B34: Follow-on equity | C34: =LBO!$D$17 -> 45672 | D34: =-LBO!$D$18 -> -67 | E34: =-LBO!$D$18 -> -67 | F34: =-LBO!$D$18 -> -67 | G34: =-LBO!$D$18 -> -67 | H34: =-LBO!$D$18 -> -67
B35: Exit proceeds | C35: =LBO!$D$111 -> 46142 | D35: =LBO!E111*-(D33+D34) -> 17.225144 | E35: =LBO!F111*-(E33+E34) -> 59.716562 | F35: =LBO!G111*-(F33+F34) -> 102.20798 | G35: =LBO!H111*-(G33+G34) -> 144.6994 | H35: =LBO!I111*-(H33+H34) -> 187.19082
B36: IRR (XIRR) | D36: =IF(D35>0,XIRR(D33:D35,$C33:$C35),-1) -> -0.65879475 | E36: =IF(E35>0,XIRR(E33:E35,$C33:$C35),-1) -> -0.23360215 | F36: =IF(F35>0,XIRR(F33:F35,$C33:$C35),-1) -> -0.0034077005 | G36: =IF(G35>0,XIRR(G33:G35,$C33:$C35),-1) -> 0.15251589 | H36: =IF(H35>0,XIRR(H33:H35,$C33:$C35),-1) -> 0.27133591
B38: Row 2: entry equity | C38: =LBO!$D$7 -> 44652 | D38: =-(LBO!$D$8*LBO!$D$9-LBO!$D$13-LBO!$D$15) -> -36 | E38: =-(LBO!$D$8*LBO!$D$9-LBO!$D$13-LBO!$D$15) -> -36 | F38: =-(LBO!$D$8*LBO!$D$9-LBO!$D$13-LBO!$D$15) -> -36 | G38: =-(LBO!$D$8*LBO!$D$9-LBO!$D$13-LBO!$D$15) -> -36 | H38: =-(LBO!$D$8*LBO!$D$9-LBO!$D$13-LBO!$D$15) -> -36
B39: Follow-on equity | C39: =LBO!$D$17 -> 45672 | D39: =-LBO!$D$18 -> -67 | E39: =-LBO!$D$18 -> -67 | F39: =-LBO!$D$18 -> -67 | G39: =-LBO!$D$18 -> -67 | H39: =-LBO!$D$18 -> -67
B40: Exit proceeds | C40: =LBO!$D$112 -> 46325 | D40: =LBO!E112*-(D38+D39) -> 8.0086814 | E40: =LBO!F112*-(E38+E39) -> 50.5001 | F40: =LBO!G112*-(F38+F39) -> 92.991518 | G40: =LBO!H112*-(G38+G39) -> 135.48294 | H40: =LBO!I112*-(H38+H39) -> 177.97435
B41: IRR (XIRR) | D41: =IF(D40>0,XIRR(D38:D40,$C38:$C40),-1) -> -0.69813904 | E41: =IF(E40>0,XIRR(E38:E40,$C38:$C40),-1) -> -0.24469555 | F41: =IF(F40>0,XIRR(F38:F40,$C38:$C40),-1) -> -0.036712594 | G41: =IF(G40>0,XIRR(G38:G40,$C38:$C40),-1) -> 0.10084161 | H41: =IF(H40>0,XIRR(H38:H40,$C38:$C40),-1) -> 0.2045962
B43: Row 3: entry equity | C43: =LBO!$D$7 -> 44652 | D43: =-(LBO!$D$8*LBO!$D$9-LBO!$D$13-LBO!$D$15) -> -36 | E43: =-(LBO!$D$8*LBO!$D$9-LBO!$D$13-LBO!$D$15) -> -36 | F43: =-(LBO!$D$8*LBO!$D$9-LBO!$D$13-LBO!$D$15) -> -36 | G43: =-(LBO!$D$8*LBO!$D$9-LBO!$D$13-LBO!$D$15) -> -36 | H43: =-(LBO!$D$8*LBO!$D$9-LBO!$D$13-LBO!$D$15) -> -36
B44: Follow-on equity | C44: =LBO!$D$17 -> 45672 | D44: =-LBO!$D$18 -> -67 | E44: =-LBO!$D$18 -> -67 | F44: =-LBO!$D$18 -> -67 | G44: =-LBO!$D$18 -> -67 | H44: =-LBO!$D$18 -> -67
B45: Exit proceeds | C45: =LBO!$D$113 -> 46507 | D45: =LBO!E113*-(D43+D44) -> 0 | E45: =LBO!F113*-(E43+E44) -> 40.941674 | F45: =LBO!G113*-(F43+F44) -> 83.433092 | G45: =LBO!H113*-(G43+G44) -> 125.92451 | H45: =LBO!I113*-(H43+H44) -> 168.41593
B46: IRR (XIRR) | D46: =IF(D45>0,XIRR(D43:D45,$C43:$C45),-1) -> -1 | E46: =IF(E45>0,XIRR(E43:E45,$C43:$C45),-1) -> -0.26316639 | F46: =IF(F45>0,XIRR(F43:F45,$C43:$C45),-1) -> -0.063579559 | G46: =IF(G45>0,XIRR(G43:G45,$C43:$C45),-1) -> 0.062416737 | H46: =IF(H45>0,XIRR(H43:H45,$C43:$C45),-1) -> 0.15572877
B48: Row 4: entry equity | C48: =LBO!$D$7 -> 44652 | D48: =-(LBO!$D$8*LBO!$D$9-LBO!$D$13-LBO!$D$15) -> -36 | E48: =-(LBO!$D$8*LBO!$D$9-LBO!$D$13-LBO!$D$15) -> -36 | F48: =-(LBO!$D$8*LBO!$D$9-LBO!$D$13-LBO!$D$15) -> -36 | G48: =-(LBO!$D$8*LBO!$D$9-LBO!$D$13-LBO!$D$15) -> -36 | H48: =-(LBO!$D$8*LBO!$D$9-LBO!$D$13-LBO!$D$15) -> -36
B49: Follow-on equity | C49: =LBO!$D$17 -> 45672 | D49: =-LBO!$D$18 -> -67 | E49: =-LBO!$D$18 -> -67 | F49: =-LBO!$D$18 -> -67 | G49: =-LBO!$D$18 -> -67 | H49: =-LBO!$D$18 -> -67
B50: Exit proceeds | C50: =LBO!$D$114 -> 46690 | D50: =LBO!E114*-(D48+D49) -> 0 | E50: =LBO!F114*-(E48+E49) -> 30.919347 | F50: =LBO!G114*-(F48+F49) -> 73.410765 | G50: =LBO!H114*-(G48+G49) -> 115.90218 | H50: =LBO!I114*-(H48+H49) -> 158.3936
B51: IRR (XIRR) | D51: =IF(D50>0,XIRR(D48:D50,$C48:$C50),-1) -> -1 | E51: =IF(E50>0,XIRR(E48:E50,$C48:$C50),-1) -> -0.29123263 | F51: =IF(F50>0,XIRR(F48:F50,$C48:$C50),-1) -> -0.087772027 | G51: =IF(G50>0,XIRR(G48:G50,$C48:$C50),-1) -> 0.031598465 | H51: =IF(H50>0,XIRR(H48:H50,$C48:$C50),-1) -> 0.11770739
...
